Workbook

Sheet INVOICE
A1: CALIFOR UPHOLSTERY MATERIALS CO., LTD.
A2: XIN BAVET SEZ, Road No. 316A, Trapeang Bon and Prey Kokir Villages, Prey Kokir Commune, Chantrea District,
A3: Svay Rieng Province, Kingdom of Cambodia.
A4: VAT:L001-901903209
A5: Tel: +855 975910636
A7: INVOICE
A8: RefNo.: | B8: ='PACKING LIST'!B7
A9: Invoice No: | B9: ='PACKING LIST'!B8
A10: Date: | B10: ='PACKING LIST'!B9
A11: To: | B11: WANEK FURNITURE CO., LTD
B12: Lot D_5A_CN, D_5C_CN, D_5E_CN, My Phuoc 3 Industrial Park,
B13: Thoi Hoa Ward, Ho Chi Minh City, Vietnam.
A14: From : | B14: ='Detail packing list'!B13
A15: To : | B15: HO CHI MINH, VIET NAM.
A16: Payment Term: | B16: ='Detail packing list'!B15
A17: Origin of goods: | B17: ='Detail packing list'!B16
A18: Shipping term: | B18: ='Detail packing list'!B17
A19: Shipped Per: | B19: BY TRUCK FROM BAVET, SVAY RIENG, CAMBODIA TO HO CHI MINH, VIETNAM.
A24: PO number | B24: Item No. | C24: Description of Goods | D24: Quantity | E24: Unit | F24: Unit Price (USD) | G24: Amount (USD)
A25: PT29J74 | C25: 140522 | D25: 48863.8 | E25: SF | F25: 1.42 | G25: =D25 * F25
A26: PT2CB00 | C26: 140478 | D26: 14661.7 | E26: SF | F26: 0.86 | G26: =D26 * F26
A27: PT2CB01 | C27: 140478 | D27: 61888.7 | E27: SF | F27: 0.86 | G27: =D27 * F27
A28: PT2CB13 | C28: 140478 | D28: 49032 | E28: SF | F28: 0.86 | G28: =D28 * F28
A29: PT2CB07 | C29: 140519 | D29: 29939.5 | E29: SF | F29: 0.89 | G29: =D29 * F29
A30: PT2CK66 | C30: 140478 | D30: 58311.1 | E30: SF | F30: 0.86 | G30: =D30 * F30
A31: PT2CK68 | C31: 140478 | D31: 30611.9 | E31: SF | F31: 0.86 | G31: =D31 * F31
A32: PT2CT53 | C32: 140478 | D32: 30425.6 | E32: SF | F32: 0.86 | G32: =D32 * F32
C33: TOTAL | D33: =SUM(D25:D32) | G33: =SUM(G25:G32)
A37: =A1

Sheet PACKING LIST
A1: CALIFOR UPHOLSTERY MATERIALS CO., LTD.
A2: XIN BAVET SEZ, Road No. 316A, Trapeang Bon and Prey Kokir Villages, Prey Kokir Commune, Chantrea District,
A3: Svay Rieng Province, Kingdom of Cambodia.
A4: VAT:L001-901903209
A5: Tel: +855 975910636
A6: PACKING LIST
A7: RefNo.: | B7: ='Detail packing list'!B7
A8: Invoice No | B8: ='Detail packing list'!B8
A9: Date | B9: ='Detail packing list'!B9
A10: To | B10: =INVOICE!B11
B11: Lot D_5A_CN, D_5C_CN, D_5E_CN, My Phuoc 3 Industrial Park,
B12: Thoi Hoa Ward, Ho Chi Minh City, Vietnam.
A13: From | B13: BAVET, SVAY RIENG, CAMBODIA
A14: To | B14: =INVOICE!B15
A15: Payment Term: | B15: T/T 43 days B/L date
A16: Origin of goods: | B16: CAMBODIA
A17: Shipping term: | B17: DAP: HCM
A20: PO number | B20: Item No. | C20: Description of Goods | D20: PALLET NO.# | E20: PCS | F20: Quantity (SF) | G20: Unit | H20: Net Weight (Kgs) | I20: Gross Weight (Kgs) | J20: Volume (CBM) | K20: Container number
A21: PT2CK66 | C21: 140478 | D21: 1-12 | E21: 234 | F21: 9089.7 | G21: SF | H21: 631.5 | I21: 676.5 | J21: 2.178
A22: PT2CK66 | C22: 140478 | E22: 290 | F22: 11343.8 | G22: SF | H22: 772.5 | I22: 817.5 | J22: 2.7324
A23: PT2CK66 | C23: 140478 | D23: 3-12 | E23: 265 | F23: 10322.2 | G23: SF | H23: 711 | I23: 756 | J23: 2.6136
A24: PT2CK66 | C24: 140478 | D24: 4-12 | E24: 265 | F24: 10201.4 | G24: SF | H24: 692.5 | I24: 737.5 | J24: 2.4552
A25: PT2CK66 | C25: 140478 | E25: 175 | F25: 6884.8 | G25: SF | H25: 461.5 | I25: 506.5 | J25: 2.0592
A26: PT2CK66 | C26: 140478 | D26: 6-12 | E26: 254 | F26: 9850.2 | G26: SF | H26: 642.0556 | I26: 684.3889 | J26: 2.2352
A27: PT2CK66 | C27: 140478 | E27: 2 | F27: 76 | G27: SF | H27: 5.0556 | I27: 5.3889 | J27: 0.0176
A28: PT2CK66 | C28: 140478 | E28: 14 | F28: 543 | G28: SF | H28: 35.3888 | I28: 37.7222 | J28: 0.1232
A29: PT2CK68 | C29: 140478 | E29: 280 | F29: 10978.2 | G29: SF | H29: 748.5 | I29: 793.5 | J29: 2.4948
A30: PT2CK68 | C30: 140478 | D30: 8-12 | E30: 270 | F30: 10443.4 | G30: SF | H30: 714 | I30: 759 | J30: 2.6136
A31: PT2CK68 | C31: 140478 | D31: 9-12 | E31: 235 | F31: 9190.3 | G31: SF | H31: 631.5 | I31: 676.5 | J31: 2.2968
A32: PT2CT53 | C32: 140478 | D32: 10-12 | E32: 290 | F32: 10603.4 | G32: SF | H32: 732 | I32: 777 | J32: 2.574
A33: PT2CT53 | C33: 140478 | D33: 11-12 | E33: 290 | F33: 10849.5 | G33: SF | H33: 746.5 | I33: 791.5 | J33: 2.5344
A34: PT2CT53 | C34: 140478 | D34: 12-12 | E34: 235 | F34: 8972.7 | G34: SF | H34: 616.5 | I34: 661.5 | J34: 2.5344
A35: PT2CB01 | C35: TOTAL： | D35: 10-21 | E35: =SUM(E21:E34) | F35: =SUM(F21:F34) | G35: SF | H35: =SUM(H21:H34) | I35: =SUM(I21:I34) | J35: =SUM(J21:J34)
A36: PT2CB01 | C36: TOTAL： | D36: 11-21 | E36: =SUM(E21:E49,E21:E34) | F36: =SUM(F21:F49,F21:F34) | G36: SF | H36: =SUM(H21:H49,H21:H34) | I36: =SUM(I21:I49,I21:I34) | J36: =SUM(J21:J49,J21:J34)
A37: PT2CB01 | C37: 140478 | D37: 12-21 | E37: 270 | F37: 10130.5 | G37: SF | H37: 675.5 | I37: 720.5 | J37: 2.6532
A38: Says total : | C38: 140478 | G38: SF | H38: 717.3913 | I38: 760.4348 | J38: 2.5378
A39: Total Net Weight: | C39: =H28 | G39: SF | H39: 32.6087 | I39: 34.5652 | J39: 0.1154
A40: Total G. Weight: | C40: =I28 | D40: 14-21 | E40: 250 | F40: 9481.5 | G40: SF | H40: 644.1964 | I40: 684.375 | J40: 2.2982
A41: PT2CB13 | C41: 140478 | E41: 30 | F41: 1067.6 | G41: SF | H41: 77.3036 | I41: 82.125 | J41: 0.2758
A42: Warning information | C42: 140478 | D42: 15-21 | E42: 280 | F42: 10549.6 | G42: SF | H42: 719.5 | I42: 764.5 | J42: 2.6532
...

Sheet Detail packing list
A1: CALIFOR UPHOLSTERY MATERIALS CO., LTD.
A2: XIN BAVET SEZ, Road No. 316A, Trapeang Bon and Prey Kokir Villages, Prey Kokir Commune, Chantrea District,
A3: Svay Rieng Province, Kingdom of Cambodia.
A4: VAT:L001-901903209
A5: Tel: +855 975910636
A6: DETAIL PACKING LIST
A7: RefNo.: | B7: CLF2026-011
A8: Invoice No | B8: CLW26003
A9: Date | B9: 2026-01-08 00:00:00
A10: To | B10: =INVOICE!B11
B11: Lot D_5A_CN, D_5C_CN, D_5E_CN, My Phuoc 3 Industrial Park,
B12: Thoi Hoa Ward, Ho Chi Minh City, Vietnam.
A13: From | B13: BAVET, SVAY RIENG, CAMBODIA
A14: To | B14: =INVOICE!B15
A15: Payment Term: | B15: T/T 43 days B/L date
A16: Origin of goods: | B16: CAMBODIA
A17: Shipping term: | B17: DAP: HCM
A20: PO number | B20: Item No. | C20: Description of Goods | D20: PALLET NO.# | E20: PCS | F20: Quantity (SF) | G20: Unit | H20: Net Weight (Kgs) | I20: Gross Weight (Kgs) | J20: Volume (CBM) | K20: Container number | L20: Remark
A21: PT2CK66 | C21: 140478 | D21: 1-12 | E21: 234 | F21: 9089.7 | G21: SF | H21: 631.5 | I21: 676.5 | J21: 2.178
A22: PT2CK66 | C22: 140478 | E22: 290 | F22: 11343.8 | G22: SF | H22: 772.5 | I22: 817.5 | J22: 2.7324
A23: PT2CK66 | C23: 140478 | D23: 3-12 | E23: 265 | F23: 10322.2 | G23: SF | H23: 711 | I23: 756 | J23: 2.6136
A24: PT2CK66 | C24: 140478 | D24: 4-12 | E24: 265 | F24: 10201.4 | G24: SF | H24: 692.5 | I24: 737.5 | J24: 2.4552
A25: PT2CK66 | C25: 140478 | E25: 175 | F25: 6884.8 | G25: SF | H25: 461.5 | I25: 506.5 | J25: 2.0592
A26: PT2CK66 | C26: 140478 | D26: 6-12 | E26: 254 | F26: 9850.2 | G26: SF | H26: 642.0556 | I26: 684.3889 | J26: 2.2352
A27: PT2CK66 | C27: 140478 | E27: 2 | F27: 76 | G27: SF | H27: 5.0556 | I27: 5.3889 | J27: 0.0176
A28: PT2CK66 | C28: 140478 | E28: 14 | F28: 543 | G28: SF | H28: 35.3888 | I28: 37.7222 | J28: 0.1232
A29: PT2CK68 | C29: 140478 | E29: 280 | F29: 10978.2 | G29: SF | H29: 748.5 | I29: 793.5 | J29: 2.4948
A30: PT2CK68 | C30: 140478 | D30: 8-12 | E30: 270 | F30: 10443.4 | G30: SF | H30: 714 | I30: 759 | J30: 2.6136
A31: PT2CK68 | C31: 140478 | D31: 9-12 | E31: 235 | F31: 9190.3 | G31: SF | H31: 631.5 | I31: 676.5 | J31: 2.2968
A32: PT2CT53 | C32: 140478 | D32: 10-12 | E32: 290 | F32: 10603.4 | G32: SF | H32: 732 | I32: 777 | J32: 2.574
A33: PT2CT53 | C33: 140478 | D33: 11-12 | E33: 290 | F33: 10849.5 | G33: SF | H33: 746.5 | I33: 791.5 | J33: 2.5344
A34: PT2CT53 | C34: 140478 | D34: 12-12 | E34: 235 | F34: 8972.7 | G34: SF | H34: 616.5 | I34: 661.5 | J34: 2.5344
A35: PT2CB01 | C35: TOTAL： | D35: 10-21 | E35: =SUM(E21:E34) | F35: =SUM(F21:F34) | G35: SF | H35: =SUM(H21:H34) | I35: =SUM(I21:I34) | J35: =SUM(J21:J34)
A36: PT2CB01 | C36: TOTAL： | D36: 11-21 | E36: =SUM(E21:E49,E21:E34) | F36: =SUM(F21:F49,F21:F34) | G36: SF | H36: =SUM(H21:H49,H21:H34) | I36: =SUM(I21:I49,I21:I34) | J36: =SUM(J21:J49,J21:J34)
A37: PT2CB01 | C37: TOTAL： | D37: =D72+D55 | E37: =E72+E55 | F37: =F72+F55 | G37: SF | H37: =H72+H55 | I37: =I72+I55 | J37: =J72+J55
A38: Says total : | C38: 140478 | G38: SF | H38: 717.3913 | I38: 760.4348 | J38: 2.5378
A39: Total Net Weight: | C39: =H73 | G39: SF | H39: 32.6087 | I39: 34.5652 | J39: 0.1154
A40: Total G. Weight: | C40: =I73 | D40: 14-21 | E40: 250 | F40: 9481.5 | G40: SF | H40: 644.1964 | I40: 684.375 | J40: 2.2982
A41: PT2CB13 | C41: 140478 | E41: 30 | F41: 1067.6 | G41: SF | H41: 77.3036 | I41: 82.125 | J41: 0.2758
A42: Warning information | C42: 140478 | D42: 15-21 | E42: 280 | F42: 10549.6 | G42: SF | H42: 719.5 | I42: 764.5 | J42: 2.6532
...

Sheet DeepSheet
A1: invoice_no
A2: ref_no
A3: date
A4: net | B4: 22372.5
A5: gross | B5: 23857.5

Sheet Update Container No.
A1: Vendor Name | B1: Item No | C1: Item DSC | D1: Order No | E1: Original Order Q'ty | F1: Vendor ETD | G1: Container No | H1: Remark
A2: … | B2: … | C2: … | D2: … | E2: … | F2: … | G2: …
A3: … | B3: … | C3: … | D3: … | E3: … | F3: … | G3: …
A4: … | B4: … | C4: … | D4: … | E4: … | F4: … | G4: …
A5: … | B5: … | C5: … | D5: … | E5: … | F5: … | G5: …
A6: … | B6: … | C6: … | D6: … | E6: … | F6: … | G6: …
A7: … | B7: … | C7: … | D7: … | E7: … | F7: … | G7: …

Sheet TK SX
A2: HẢI QUAN VIỆT NAM | K2: TỜ KHAI HÀNG HÓA NHẬP KHẨU
A3: 0 | J3: =+IF(A3=0,"Bản lưu Hải quan","Bản lưu người khai Hải quan") | AF3: HQ/2002-NK
A4: TỔNG CỤC HẢI QUAN | M4: Tờ khai số: | T4: /NK/ / | Y4: Cán bộ đăng ký (Ký, ghi rõ họ tên)
A5: Cục Hải quan | E5: Tỉnh Bình Dương | M5: Ngày đăng ký: | T5: 6
A6: Chi cục Hải quan: | F6: Chi cục HQ Sóng Thần | M6: Số lượng phụ lục tờ khai: | U6: 0
A7: A-PHẦN DÀNH CHO NGƯỜI KHAI HẢI QUAN KÊ KHAI
A8: 1.Người nhập khẩu | F8: 3 | G8: 7 | H8: 0 | I8: 0 | J8: 5 | K8: 3 | L8: 9 | M8: 0 | N8: 0 | O8: 0 | S8: 5. Loại hình: | Y8: 6.Giấy phép( nếu có) | AE8: 7.Hợp đồng
B10: CÔNG TY TNHH KỸ NGHỆ GỖ HOA NÉT | T10: KD | V10: ĐT | X10: GC | Y10: Số : | AA10: 461043000383 | AE10: Số: | AF10: =INVOICE!#REF!
B11: WANEK FURNITURE CO., LTD | T11: SXXK | W11: NTX | Y11: Ngày: | AA11: 19/06/2008 | AE11: Ngày : | AG11: 40315
B12: Ấp Tân Long, xã Tân Hiệp, huyện Tân Uyên, tỉnh Bình Dương | T12: TN | Y12: Ngày hết hạn: | AE12: Ngày hết hạn:
A13: 2. Người xuất khẩu | S13: 8. Hoá đơn thương mại | Y13: 9. Phương tiện vận tải | AE13: 10.Vận tải đơn
B15: =INVOICE!A1 | S15: Số : | Y15: Tên, số hiệu: | AE15: Số: | AF15: KAOHCM1005047
B16: =INVOICE!A2 | S16: =INVOICE!B10 | Y16: =INVOICE!B18
S17: Ngày: | U17: =INVOICE!#REF! | Y17: Ngày đến: | AB17: 40333 | AE17: Ngày: | AG17: 40328
A18: 3. Người ủy thác | S18: 11. Nước xuất khẩu: | Y18: 12. Cảng, địa điểm | AE18: 13. Cảng, địa điểm
S20: CHINA | Y20: xếp hàng: | AE20: dỡ hàng:
Y21: =INVOICE!B14 | AE21: CÁT LÁI
W22: C | X22: N
A23: 4.Đại lý làm thủ tục | S23: 14. Điều kiện | X23: 15. Đồng tiền | AB23: U | AC23: S | AD23: D | AE23: 16. Phương thức
A24: hải quan | S24: giao hàng: | X24: thanh toán: | AE24: thanh toán:
S25: FOB | AA25: (VNĐ/USD) | AE25: TTR
X26: Tỷ giá | AA26: 18544
X27: tính thuế:
A28: Số | B28: 17. TÊN HÀNG | O28: 18. MÃ SỐ | S28: 19.XUẤT | V28: 20. LƯỢNG | Y28: 21. ĐƠN VỊ | AB28: 22. ĐƠN GIÁ | AF28: 23. TRỊ GIÁ
A29: TT | B29: QUY CÁCH PHẨM CHẤT | O29: HÀNG HÓA | S29: XỨ | Y29: TÍNH | AB29: NGUYÊN TỆ | AF29: NGUYÊN TỆ
A30: 1 | B30: NPL SẢN XUẤT ĐỒ GỖ NỘI NGOẠI THẤT | AF30: =+AB30*V30
A31: =1+A30 | B31: Chi tiết theo phụ lục đính kèm
A32: =1+A31 | O32: =#REF! | AF32: 7.89
A33: TC: | C33: 37 | G33: 672 | O33: Hàng chung TK: | AD33: Cộng: | AF33: =SUM(AF30:AI32)
A34: Số | B34: 24.THUẾ NHẬP KHẨU | O34: 25. THUẾ GTGT( HOẶC TTĐB) | AD34: 26. THU KHÁC
A35: TT | B35: Trị giá tính thuế | G35: Thuế suất(%) | J35: Tiền thuế | O35: Trị giá tinh thuế | U35: Thuế suất(%) | X35: Tiền thuế | AD35: Tỷ lệ( %) | AG35: Số tiền
A36: 1 | B36: 39054129 | G36: 0.03 | J36: =+G36*B36 | O36: Haøng khoâng thuoäc ñoái töôïng chòu thueá GTGT
A37: =1+A36 | B37: 12088183 | G37: 0.05 | J37: =+G37*B37 | O37: theo thoâng tö: 129/2008/TT-BTC 26/12/08
A38: =1+A37
H39: Cộng: | J39: =SUM(J36:N38)
A40: 27. Tổng số tiền thuế và thu khác( ô 24+25+26): Bằng số : | P40: =+J39+X39
A41: Bằng chữ : | E41: một triệu bảy trăm bảy mươi sáu ngàn không trăm ba mươi ba đồng
A42: 28. Chứng từ đi kèm: | I42: Bản chính | N42: Bản sao | S42: 29.Tôi xin cam đoan, chịu trách nhiệm trước pháp luật về những nội
A43: – Hợp đồng thương mai : | H43: : | O43: 1 | S43: dung khai báo trên tờ khai này.
A44: – Hoá đơn thương mại | H44: : | J44: 1 | W44: Ngày ……...tháng …… năm 2010
...

Sheet TK SXXK
M5: ÑT/SXX/I43H
E6: Bình Döông
F7: Soùng Thaàn
E10: 3 7 0 0 9 3 7 2 4 1
B11: C.TY | D11: TNHH KYÕ NGHEÄ GOÃ HOA NEÙT | P11: 461043000383 | S11: =INVOICE!#REF!
B12: Aáp Taân Long, Xaõ Taân Hieäp , Huyeän Taân Uyeân, Bình Döông | Q12: 19/06/2008 | T12: 23/07/2014
B13: (WANEK FURNITURE CO.,LTD)
B15: =INVOICE!A1 | P15: =INVOICE!B18 | S15: BGNL59406189
B16: =INVOICE!A2 | M16: =INVOICE!B10 | U16: 16/08/2014
M17: 10/08/2014 | Q17: =+U16+5
M20: CHINA | P20: SHANGHAI | T20: KV I (CAÙT LAÙI)
N22: C | O22: N
Q23: U S D
M25: FOB SHANGHAI | P25: 21246 | S25: T/T
M26: (CHINA)
Q27: $/m | R27: $/m2 | V27: =#REF!
B28: NPL SX ÑOÀ GOÃ NOÄI NGOAÏI THAÁT & ÑOÀ TRANG TRÍ BAÈNG VAÛI | T28: =SUM(PLSX!R9:S20)
B29: Chi tiết theo phụ lục đính kèm | V29: =#REF!
D30: hang chung cont, bill | M30: =+PLSX!G31 | O30: =+PLSX!K31 | T30: =PLSX!O31 | V30: =SUM(V28:W29)
B31: TC: | D31: ='Detail packing list'!F55 | E31: =+'Detail packing list'!F20 | F31: ='Detail packing list'!B74 | H31: 0 | T31: =SUM(T28:U30)
A32: STT | B32: Số hiệu container | F32: Loại container | I32: Seal No
A33: 1. | B33: =+'danh sach cont '!B2 | F33: Container 40 | I33: =+'danh sach cont '!C2
A34: 2. | B34: =+'danh sach cont '!B3 | F34: Container 40 | I34: =+'danh sach cont '!C3
A35: 3. | B35: =+'danh sach cont '!B4 | F35: Container 40 | I35: =+'danh sach cont '!C4
A36: 4. | B36: =+'danh sach cont '!B5 | F36: Container 40 | I36: =+'danh sach cont '!C5
A37: 5. | B37: =+'danh sach cont '!B6 | F37: Container 40 | I37: =+'danh sach cont '!C6
A38: 6. | B38: =+'danh sach cont '!B7 | F38: Container 40 | I38: =+'danh sach cont '!C7
A39: 7. | B39: =+'danh sach cont '!B8 | F39: Container 40 | I39: =+'danh sach cont '!C8
A40: 8 | B40: =+'danh sach cont '!B9 | F40: Container 40 | I40: =+'danh sach cont '!C9
A41: 9 | B41: =+'danh sach cont '!B10 | F41: Container 20 | I41: =+'danh sach cont '!C10
G42: =PLSX!F56
J43: =$G$42+$N$42
C48: haøng coù baûo hieåm

Sheet PLSX
J2: 1/1
L4: / /2012
P8: $/m | Q8: $/m2 | T8: =O31/SUM(PLSX!R9:S30)
A9: =M9*C10 | B9: =VLOOKUP(G10,'danh sach NPL'!$C$8:$H$65536,2,0)&" "&'Detail packing list'!B21&" "&'Detail packing list'!C21 | I9: =VLOOKUP(G10,'danh sach NPL'!$C$8:$H$65536,4,0) | K9: China | M9: =INVOICE!D25 | O9: M | P9: =INVOICE!#REF! | Q9: =R9/A9 | R9: =P9*M9 | T9: =$T$8*P9*M9
B10: Khổ: | C10: ='Detail packing list'!#REF! | D10: ='Detail packing list'!F21 | E10: =M9*C10 | F10: Mã NPL: | G10: =VLOOKUP(INVOICE!B25,Sheet1!$B$3:$H$6000,7,0) | Q10: $/m2)
A11: =M11*C12 | B11: =VLOOKUP(G12,'danh sach NPL'!$C$8:$H$65536,2,0)&" "&'Detail packing list'!B22&" "&'Detail packing list'!C22 | I11: =VLOOKUP(G12,'danh sach NPL'!$C$8:$H$65536,4,0) | K11: China | M11: =INVOICE!#REF! | O11: M | P11: =INVOICE!#REF! | Q11: =R11/A11 | R11: =P11*M11 | T11: =$T$8*P11*M11
B12: Khổ: | C12: ='Detail packing list'!#REF! | D12: ='Detail packing list'!F22 | E12: =M11*C12 | F12: Mã NPL: | G12: =VLOOKUP(INVOICE!#REF!,Sheet1!$B$3:$H$6000,7,0) | Q12: $/m2)
A13: =M13*C14 | B13: =VLOOKUP(G14,'danh sach NPL'!$C$8:$H$65536,2,0)&" "&'Detail packing list'!B23&" "&'Detail packing list'!C23 | I13: =VLOOKUP(G14,'danh sach NPL'!$C$8:$H$65536,4,0) | K13: China | M13: =INVOICE!#REF! | O13: M | P13: =INVOICE!#REF! | Q13: =R13/A13 | R13: =P13*M13 | T13: =$T$8*P13*M13
B14: Khổ: | C14: ='Detail packing list'!#REF! | D14: ='Detail packing list'!F23 | E14: =M13*C14 | F14: Mã NPL: | G14: =VLOOKUP(INVOICE!#REF!,Sheet1!$B$3:$H$6000,7,0) | Q14: $/m2)
A15: =M15*C16 | B15: =VLOOKUP(G16,'danh sach NPL'!$C$8:$H$65536,2,0)&" "&'Detail packing list'!#REF!&" "&'Detail packing list'!#REF! | I15: =VLOOKUP(G16,'danh sach NPL'!$C$8:$H$65536,4,0) | K15: China | M15: =INVOICE!#REF! | O15: M | P15: =INVOICE!#REF! | Q15: =R15/A15 | R15: =P15*M15 | T15: =$T$8*P15*M15
B16: Khổ: | C16: ='Detail packing list'!#REF! | D16: ='Detail packing list'!#REF! | E16: =M15*C16 | F16: Mã NPL: | G16: =VLOOKUP(INVOICE!#REF!,Sheet1!$B$3:$H$6000,7,0) | Q16: $/m2)
A17: =M17*C18 | B17: =VLOOKUP(G18,'danh sach NPL'!$C$8:$H$65536,2,0)&" "&'Detail packing list'!#REF!&" "&'Detail packing list'!#REF! | I17: =VLOOKUP(G18,'danh sach NPL'!$C$8:$H$65536,4,0) | K17: China | M17: =INVOICE!#REF! | O17: M | P17: =INVOICE!#REF! | Q17: =R17/A17 | R17: =P17*M17 | T17: =$T$8*P17*M17
B18: Khổ: | C18: ='Detail packing list'!#REF! | D18: ='Detail packing list'!#REF! | E18: =M17*C18 | F18: Mã NPL: | G18: =VLOOKUP(INVOICE!#REF!,Sheet1!$B$3:$H$6000,7,0) | Q18: $/m2)
A19: =M19*C20 | B19: =VLOOKUP(G20,'danh sach NPL'!$C$8:$H$65536,2,0)&" "&'Detail packing list'!#REF!&" "&'Detail packing list'!#REF! | I19: =VLOOKUP(G20,'danh sach NPL'!$C$8:$H$65536,4,0) | K19: China | M19: =INVOICE!#REF! | O19: M | P19: =INVOICE!#REF! | Q19: =R19/A19 | R19: =P19*M19 | T19: =$T$8*P19*M19
B20: Khổ: | C20: ='Detail packing list'!#REF! | D20: ='Detail packing list'!#REF! | E20: =M19*C20 | F20: Mã NPL: | G20: =VLOOKUP(INVOICE!#REF!,Sheet1!$B$3:$H$6000,7,0) | Q20: $/m2)
A21: =M21*C22 | B21: =VLOOKUP(G22,'danh sach NPL'!$C$8:$H$65536,2,0)&" "&'Detail packing list'!#REF!&" "&'Detail packing list'!#REF! | I21: =VLOOKUP(G22,'danh sach NPL'!$C$8:$H$65536,4,0) | K21: China | M21: =INVOICE!#REF! | O21: M | P21: =INVOICE!#REF! | Q21: =R21/A21 | R21: =P21*M21 | T21: =$T$8*P21*M21
B22: Khổ: | C22: ='Detail packing list'!#REF! | D22: ='Detail packing list'!#REF! | E22: =M21*C22 | F22: Mã NPL: | G22: =VLOOKUP(INVOICE!#REF!,Sheet1!$B$3:$H$6000,7,0) | Q22: $/m2)
A23: =M23*C24 | B23: =VLOOKUP(G24,'danh sach NPL'!$C$8:$H$65536,2,0)&" "&'Detail packing list'!#REF!&" "&'Detail packing list'!#REF! | I23: =VLOOKUP(G24,'danh sach NPL'!$C$8:$H$65536,4,0) | K23: China | M23: =INVOICE!#REF! | O23: M | P23: =INVOICE!#REF! | Q23: =R23/A23 | R23: =P23*M23 | T23: =$T$8*P23*M23
B24: Khổ: | C24: ='Detail packing list'!#REF! | D24: ='Detail packing list'!#REF! | E24: =M23*C24 | F24: Mã NPL: | G24: =VLOOKUP(INVOICE!#REF!,Sheet1!$B$3:$H$6000,7,0) | Q24: $/m2)
A25: =M25*C26 | B25: =VLOOKUP(G26,'danh sach NPL'!$C$8:$H$65536,2,0)&" "&'Detail packing list'!#REF!&" "&'Detail packing list'!#REF! | I25: =VLOOKUP(G26,'danh sach NPL'!$C$8:$H$65536,4,0) | K25: China | M25: =INVOICE!#REF! | O25: M | P25: =INVOICE!#REF! | Q25: =R25/A25 | R25: =P25*M25 | T25: =$T$8*P25*M25
B26: Khổ: | C26: ='Detail packing list'!#REF! | D26: ='Detail packing list'!#REF! | E26: =M25*C26 | F26: Mã NPL: | G26: =VLOOKUP(INVOICE!#REF!,Sheet1!$B$3:$H$6000,7,0) | Q26: $/m2)
A27: =M27*C28 | B27: =VLOOKUP(G28,'danh sach NPL'!$C$8:$H$65536,2,0)&" "&'Detail packing list'!#REF!&" "&'Detail packing list'!#REF! | I27: =VLOOKUP(G28,'danh sach NPL'!$C$8:$H$65536,4,0) | K27: China | M27: =INVOICE!#REF! | O27: M | P27: =INVOICE!#REF! | Q27: =R27/A27 | R27: =P27*M27 | T27: =$T$8*P27*M27
B28: Khổ: | C28: ='Detail packing list'!#REF! | D28: ='Detail packing list'!#REF! | E28: =M27*C28 | F28: Mã NPL: | G28: =VLOOKUP(INVOICE!#REF!,Sheet1!$B$3:$H$6000,7,0) | Q28: $/m2)
A29: =M29*C30 | B29: =VLOOKUP(G30,'danh sach NPL'!$C$8:$H$65536,2,0)&" "&'Detail packing list'!B55&" "&'Detail packing list'!C55 | I29: =VLOOKUP(G30,'danh sach NPL'!$C$8:$H$65536,4,0) | K29: China | M29: =INVOICE!D32 | O29: M | P29: =INVOICE!#REF! | Q29: =R29/A29 | R29: =P29*M29 | T29: =$T$8*P29*M29
B30: Khổ: | C30: ='Detail packing list'!#REF! | D30: ='Detail packing list'!#REF! | E30: =M29*C30 | F30: Mã NPL: | G30: =VLOOKUP(INVOICE!#REF!,Sheet1!$B$3:$H$6000,7,0) | Q30: $/m2)
G31: 0 | K31: 70.74 | O31: =+K31+G31 | R31: =SUM(R9:S30) | T31: =SUM(T9:U26)
T32: =T31-O31
B33: =+(T9+R9)*'TK SXXK'!$P$25 | E33: =VLOOKUP(G10,'danh sach NPL'!#REF!,6,0) | F33: =E33*B33 | I33: Haøng khoâng thuoäc ñoái töôïng chòu thueá GTGT
B35: =+(T11+R11)*'TK SXXK'!$P$25 | E35: =VLOOKUP(G12,'danh sach NPL'!#REF!,6,0) | F35: =E35*B35
B37: =+(T13+R13)*'TK SXXK'!$P$25 | F37: =E37*B37
B39: =+(T15+R15)*'TK SXXK'!$P$25 | F39: =E39*B39
B41: =+(T17+R17)*'TK SXXK'!$P$25 | F41: =E41*B41
B43: =+(T19+R19)*'TK SXXK'!$P$25 | F43: =E43*B43
B45: =+(T21+R21)*'TK SXXK'!$P$25 | F45: =E45*B45
B47: =+(T23+R23)*'TK SXXK'!$P$25 | F47: =E47*B47
B49: =+(T25+R25)*'TK SXXK'!$P$25 | F49: =E49*B49
B51: =+(T27+R27)*'TK SXXK'!$P$25 | F51: =E51*B51
B53: =+(T29+R29)*'TK SXXK'!$P$25 | F53: =E53*B53
F56: =SUM(F33:H55)

Sheet DCCK
Q1: Maãu 19-DCCK/2009
A2: COÄNG HOAØ XAÕ HOÂI CHUÛ NGHÓA VIEÄT NAM
A3: Ñoäc Laäp - Töï Do - Haïnh Phuùc
A4: -----o0o-----
A5: ÑÔN ÑEÀ NGHÒ CHUYEÅN CÖÛA KHAÅU HAØNG HOAÙ NHAÄP KHAÅU
C7: Kính gửi: | F7: - CHI CUÏC HAÛI QUAN SOÙNG THAÀN
B8: Cty | C8: TNHH KYÕ NGHEÄ GOÃ HOA NEÙT | H8: , ñeà nghò ñöôïc laøm thuû tuïc Haûi Quan taïi Chi Cuïc Haûi Quan Soùng thaàn
A9: kieåm tra Haûi Quan (neáu coù) taïi ICD Soùng Thaàn cho loâ haøng nhaäp khaåu thuoäc vaän taûi ñôn soá: | Q9: ='TK SXXK'!S15
A10: chuyeân chôû treân PTVT | F10: ='TK SXXK'!P15 | L10: tôùi cöûa khaåu nhaäp ngaøy | R10: ='TK SXXK'!Q17
B11: - Teân haøng | E11: : | F11: ='TK SXXK'!B28
B12: - Löôïng haøng | E12: : | F12: ='TK SXXK'!D31 | G12: 0 | H12: ='TK SXXK'!F31 | J12: 0
B13: - Trò giaù | E13: : | F13: ='TK SXXK'!T31 | G13: 0
B14: - Goàm | E14: : | G14: container hoaëc xe chuyeân duøng coù soá hieäu
B15: Tuyeán ñöôøng vaän chuyeån:
G16: vôùi chieàu daøi: | K16: Thôøi gian vaän chuyeån:
B17: Coâng ty TNHH KYÕ NGHEÄ GOÃ HOA NEÙT cam keát chòu traùch nhieäm tröôùc phaùp luaät veà:
A18: 1. Ñaûm baûo söï nguyeân traïng haøng hoaù vaø caùc nieâm phong haûi quan, nieâm phong haõng taøu cho tôùi khi baøn giao cho Chi Cuïc Haûi Quan ngoaøi cöûa khaåu , ñòa ñieåm kieåm tra haøng hoaù ôû noäi ñòa , giaùm saùt quaûn lyù theo qui ñònh.
A19: 2. Vaän chuyeån loâ haøng ñuùng tuyeán ñöôøng vaø thôøi gian, ñöa haøng veà ñuùng ñòa ñieåm kieåm tra ñaõ ñaêng kyù neâu treân.
K20: Bình Döông, Ngaøy thaùng naêm 2011
K21: GIAÙM ÑOÁC COÂNG TY
K22: (Kyù ghi roõ hoï teân ñoùng daáu)
C28: Kính gửi: | F28: - CHI CUÏC HAÛI QUAN | I28: ='TK SXXK'!T20
B29: Ñeà nghò laøm thuû tuïc chuyeån cöûa khaåu cho loâ haøng neâu treân cuûa Coâng ty | S29: =C8
A30: thuoäc tôø khai Haûi Quan soá:............./NÑT- SXX/ Ngaøy / /2011
K31: =K20
I32: Chi Cuïc HQ KCN Soùng Thaàn | K32: Chi Cuïc Haûi Quan Soùng Thaàn
K33: (Kyù teân ñoùng daáu coâng chöùc )

Sheet 00000000

Sheet 10000000

Sheet 20000000

Sheet danh sach cont 
A1: Số vận đơn | B1: Số Container | C1: Số seal
A2: BGNL59406189 | B2: DFSU6959629 | C2: HD3313974
A3: BGNL59406189 | B3: HDMU6184442 | C3: HD3313980
A4: BGNL59406189 | B4: DFSU6833245 | C4: HD3313990
A5: BGNL59406189 | B5: HDMU6872419 | C5: HD3313972
A6: BGNL59406189 | B6: HDMU6732206 | C6: HD3313979
A7: BGNL59406189 | B7: HMMU6001046 | C7: HD3313968
A8: BGNL59406189 | B8: TCNU7652731 | C8: HD3313945
A9: BGNL59406189 | B9: BMOU5180545 | C9: HD3313960
A10: BGNL59406189 | B10: BMOU2317450 | C10: HD3313977

Sheet cong van 
A2: CTY TNHH KỸ NGHỆ GỖ HOA NÉT | C2: COÄNG HOØA XAÕ HOÄI CHUÛ NGHÓA VIEÄT NAM
C3: Độc lập-Töï do – Haïnh phuùc
A4: 1083 | B4: /CVCK-2014 | C4: ------*--*------
C5: Bình Dương, ngày 19 tháng 08 năm 2014
A7: CÔNG VĂN CAM KẾT
A8: (V/v: Nguyên phụ liệu nhập về chỉ để sản xuất hàng xuất khẩu)
B9: KÍNH GÔÛI: LAÕNH ÑAÏO CHI CUÏC HAÛI QUAN SOÙNGTHAÀN
A11: Coâng ty TNHH KYÕ NGHEÄ GOÃ HOA NEÙT (Teân giao dòch – WANEK FURNITURE
A12: LIMITED LIABILITY COMPANY) laø Doanh nghieäp coù 100% voán ñaàu tö nöôùc ngoaøi. Truï sôû
A13: vaø nhaø xöôûng ñaët taïi: Số 11, VSIP II, đường số 6, Khu công nghiệp Việt Nam–Singapore II,
A14: KLP Công nghiệp –DV - Đô thị Bình Dương, P. Hòa Phú, TP.Thủ Dầu Một, Tỉnh Bình Dương
A15: Ñöôïc thaønh laäp theo Giaáp pheùp ñaàu tö soá: 461043000383 ngaøy 19 thaùng 06 naêm 2008
A17: Muïc tieâu vaø phaïm vi kinh doanh cuûa Doanh nghieäp: chuyeân saûn xuaát, gia coâng ñoà
A18: noäi ngoaïi thaát hoaëc keát hôïp giöõa goã, vaûi, da, kính, kim loaïi, ñaù; saûn xuaát gia coâng caùc phuï
A19: tuøng, chi tieát baèng kim loaïi, vaø caùc phuï kieän khaùc coù lieân quan.
A20: Coâng ty chuùng toâi coù kyù hôïp ñoàng nhaäp khaåu soá | I20: ='TK SXXK'!S11 | J20: ngaøy | K20: ='TK SXXK'!T12
A21: vôùi coâng ty | B21: ='TK SXXK'!B15
A22: vôùi chi tieát nhö sau:
A23: - | B23: Teân haøng | C23: : | H23: Vải.
A24: - | B24: Trò giaù hôïp ñoàng | C24: : | H24: ='TK SXXK'!T28
A25: - | B25: Vaän ñôn soá | C25: : | H25: ='TK SXXK'!S15
A26: - | B26: Soá kieän | C26: : | H26: ='TK SXXK'!D31
A27: - | B27: Troïng löôïng | C27: : | H27: ='TK SXXK'!F31
A29: Coâng ty chuùng toâi cam keát:
A30: - Nguyeân phuï lieäu nhaäp veà chæ nhaèm muïc ñích phuïc vuï saûn xuaát cuûa coâng ty
A31: - Saûn phaåm saûn xuaát nhaèm muïc ñích xuaát khaåu khoâng tieâu thuï taïi thò tröôøng Vieät Nam.
A33: Neáu coù gì sai traùi Coâng ty chuùng toâi xin chòu hoaøn toaøn traùch nhieäm tröôùc Phaùp luaät vaø
A34: caùc quy ñònh khaùc cuûa Haûi Quan.
A35: Chaân thaønh caûm ôn vaø traân troïng kính chaøo!
H36: COÂNG TY TNHH KYÕ NGHEÄ GOÃ HOA NEÙT

Sheet danh sach NPL
B1: BẢNG ĐĂNG KÝ DANH MỤC NGUYÊN VẬT LIỆU NHẬP KHẨU
B2: ĐỂ TRỰC TIẾP SẢN XUẤT HÀNG XUẤT KHẨU
G3: Mẫu: 06/ĐKNLNK/2006
C6: ngày………tháng……..năm………
A8: STT | B8: Tên nguyên phụ liệu | C8: Mã NPL | D8: Tên nguyên phụ liệu | E8: Mã HS | F8: Mã HS 2012 | G8: Đơn vị tính | H8: Nguyên phụ liệu chính
A9: (1) | B9: (2) | C9: (3) | D9: (2) | E9: (4) | G9: (5) | H9: (6)
A10: 1 | B10: Vải 43% polyester 57% rayon | C10: 1001 | D10: Vải 43% polyester 57% rayon | E10: 5801360000 | G10: M2 | H10: 0.12
A11: =A10+1 | B11: Vải 100% polyester | C11: 1002 | D11: Vải 100% polyester | E11: 5801340000 | F11: 5801.37.90 | G11: M2 | H11: 0.12
A12: =A11+1 | B12: Vải 100% polyester | C12: 1002VN | D12: Vải 100% polyester | E12: 5801340000 | F12: VN | G12: M2
A13: =A12+1 | B13: Vải 100% terylene | C13: 1003 | D13: Vải 100% terylene | E13: 5801340000 | G13: M2 | H13: 0.12
A14: =A13+1 | B14: Vải 49% polyester 51% acrylic | C14: 1004 | D14: Vải 49% polyester 51% acrylic | E14: 5801360000 | G14: M2 | H14: 0.12
A15: =A14+1 | B15: Vải 93% polyester 7% cotton | C15: 1005 | D15: Vải 93% polyester 7% cotton | E15: 5512110000 | G15: M2 | H15: 0.12
A16: =A15+1 | B16: Giả da PVC | C16: 1006 | D16: Giả da PVC | E16: 5903909090 | F16: 5903.10.00 | G16: M2 | H16: 0.12
A17: =A16+1 | B17: Da thuộc | C17: 1007 | D17: Da thuộc | E17: 4107990000 | G17: M2 | H17: 0.1
A18: =A17+1 | B18: Chỉ | C18: 1008 | D18: Chỉ | E18: 5508100000 | G18: MET | H18: 0.05
A19: =A18+1 | B19: Chỉ | C19: 1008 VN | D19: Chỉ | E19: 5508100000 | F19: VN | G19: MET
A20: =A19+1 | B20: Thùng carton | C20: 1009 | D20: Thùng carton | E20: 4819100000 | G20: CAI | H20: 0.18
A21: =A20+1 | B21: Miếng đệm | C21: 1010 | D21: Miếng đệm | E21: 5602900000 | F21: 5602.90.00 | G21: M2 | H21: 0.12
A22: =A21+1 | B22: Miếng lót nệm ghế | C22: 1011 | D22: Miếng lót nệm ghế | E22: 5603130000 | G22: M2 | H22: 0.12
A23: =A22+1 | B23: Dây kéo | C23: 1012 | D23: Dây kéo | E23: 9607110000 | F23: 9607.11.00 | G23: MET | H23: 0.2
A24: =A23+1 | B24: Đầu dây kéo | C24: 1013 | D24: Đầu dây kéo | E24: 9607200000 | F24: 9607.20.00 | G24: CAI | H24: 0.15
A25: =A24+1 | B25: Dây thun | C25: 1014 | D25: Dây thun | E25: 5604100000 | G25: MET | H25: 0.05
A26: =A25+1 | B26: Dây nẹp viền | C26: 1015 | D26: Dây nẹp viền | E26: 5607909000 | F26: 5607.90.90 | G26: MET | H26: 0.12
A27: =A26+1 | B27: Dây gân | C27: 1016 | D27: Dây gân | E27: 5607909000 | F27: 5607.90.90 | G27: MET | H27: 0.12
A28: =A27+1 | B28: Miếng dán gai | C28: 1017 | D28: Miếng dán gai | E28: 5906999000 | F28: 5906.99.90 | G28: MET | H28: 0.05
A29: =A28+1 | B29: Miếng dán lông | C29: 1018 | D29: Miếng dán lông | E29: 5906999000 | F29: 5906.99.90 | G29: MET | H29: 0.05
A30: =A29+1 | B30: Vải 90% polyester 10% cotton | C30: 1019 | D30: Vải 90% polyester 10% cotton | E30: 5512110000 | G30: M2 | H30: 0.12
A31: =A30+1 | B31: Gòn | C31: 1020 | D31: Gòn | E31: VN | G31: M2
A32: =A31+1 | B32: Nhãn mã vạch | C32: 1021 | D32: Nhãn mã vạch | E32: VN | G32: CÁI
A33: =A32+1 | B33: Túi hút ẩm | C33: 1022 | D33: Túi hút ẩm | E33: 2839900000 | F33: 2839.90.00 | G33: CÁI | H33: 0.02
A34: =A33+1 | B34: Băng keo | C34: 1023 | D34: Băng keo | E34: VN | G34: M
A35: =A34+1 | B35: Túi nylon | C35: 1024 | D35: Túi nylon | E35: VN | G35: CÁI
A36: =A35+1 | B36: Nhãn đánh số | C36: 1025 | D36: Nhãn đánh số | E36: VN | G36: CÁI
A37: =A36+1 | B37: Dây đệm | C37: 1026 | D37: Dây đệm | E37: 5603120000 | F37: 5603.12.00 | G37: MET | H37: 0.12
A38: =A37+1 | B38: Dây luồn | C38: 1027 | D38: Dây luồn | E38: 5808109000 | F38: 5808.10.90 | G38: MET | H38: 0.12
A39: =A38+1 | B39: Dựng lót | C39: 1028 | D39: Dựng lót | E39: 5603940000 | F39: 5603.94.00 | G39: MET | H39: 0.12
A40: =A39+1 | B40: Ván MDF 18mm | C40: 1029 | D40: Ván MDF 18mm | E40: VN | G40: M3
A41: =A40+1 | B41: Mút xốp | C41: 1030 | D41: Mút xốp | E41: VN | G41: M2
A42: =A41+1 | B42: Tem giấy | C42: 1031 | D42: Tem giấy | E42: VN | G42: CÁI
A43: =A42+1 | B43: Dây luồn bằng nhựa | C43: 1032 | D43: Dây luồn bằng nhựa | E43: 3926209000 | F43: 3926.20.90 | G43: MET | H43: 0.2
...

Sheet Mau 06-1 (2)
F1: Mẫu: 06/DMNVL-SXXK
A2: BAÛNG ÑAÊNG KYÙ DANH MUÏC NGUYEÂN VAÄT LIEÄU NHAÄP KHAÅU
A3: ÑEÅ TRÖÏC TIEÁP SAÛN XUAÁT HAØNG XUAÁT KHAÅU
A4: Teân doanh nghieäp : CTY TNHH KYÕ NGHEÄ GOÃ HOA NEÙT
A5: Địa chỉ :Số 11, đường số 6, KCN VSIP II, P. Hòa Phú, TP. Thủ Dầu Một, T. Bình Dương
A6: Maõ soá doanh nghieäp : 3700937241
A7: Saûn phaåm döï kieán xuaát khaåu: | C7: Saûn phaåm ñoà goã noäi ngoaïi thaát
A9: STT | B9: Teân nguyeân phuï lieäu | C9: Maõ NPL | D9: Maõ HS | E9: Ñôn vò tính | F9: Nguyeân phuï lieäu chính
A10: -1 | B10: -2 | C10: -3 | D10: -4 | E10: -5 | F10: -6
A11: 1 | B11: Vải 100% polyester | C11: 1002 | D11: 5801.37.90 | E11: M2
A12: =+A11+1 | B12: Vải 92% polyester 8% cotton | C12: 1079 | D12: 5801.37.90 | E12: M2
A13: =+A12+1 | B13: Vải 72% Polyester 28% Rayon | C13: 1073 | D13: 5801.37.90 | E13: M2
A14: =+A13+1
A15: =+A14+1
A16: =+A15+1
A17: =+A16+1
A18: =+A17+1
A19: =+A18+1
A20: =+A19+1
A21: =+A20+1
A22: =1+A21
A23: =1+A22
A24: =1+A23
A25: =1+A24
A27: Bình Döông, Ngaøy thaùng naêm 2014 | D27: =A27
A28: Công chức hải quan tiếp nhận | D28: Giaùm ñoác Doanh nghieäp
A29: (Kyù teân, ñoùng daáu coâng chöùc) | D29: (Kyù, ñoùng daáu, ghi roû hoï teân)

Sheet Sheet1
B2: Item No | C2: Vendor No | D2: Vendor Name | E2: Item Class | F2: Item DSC | G2: Item Accounting Class | H2: MA NPL | I2: ĐƠN GIÁ | J2: ĐƠN VỊ TÍNH
B3: CH-BC0174WV | C3: 2127A | D3: CHUN HUA | E3: RFMI | F3: NC BASE COAT CH-1 | G3: I | L3: #REF!
B4: CH-BC0290WV | C4: 2127A | D4: CHUN HUA | E4: RFMI | F4: BASE | G4: I | L4: #REF!
B5: CH-BC0547WV | C5: 2127A | D5: CHUN HUA | E5: RFMI | F5: 547 NC BASE COAT | G5: I | H5: 1057 | I5: 3.481 | J5: KG | L5: #REF!
B6: CH-BC0551WV | C6: 2127A | D6: CHUN HUA | E6: RFMI | F6: 551 NC BASE COAT CH | G6: I | H6: 1057 | I6: 3.76 | J6: KG | L6: #REF!
B7: CH-BC0602WV | C7: 2127A | D7: CHUN HUA | E7: RFMI | F7: 602 NC BASE COAT | G7: I | H7: 1057 | I7: 3.481 | J7: KG | L7: #REF!
B8: CH-GL0290-AWV | C8: 2127A | D8: CHUN HUA | E8: RFMI | F8: GLAZE BASE CH-3 | G8: I | L8: #REF!
B9: CH-GL0290-BWV | C9: 2127A | D9: CHUN HUA | E9: RFMI | F9: GLAZE BASE CH-4 | G9: I | L9: #REF!
B10: CH-GL0547-1WV | C10: 2127A | D10: CHUN HUA | E10: RFMI | F10: GLAZE BASE CH-9 | G10: I | H10: 1058 | I10: 10.686 | J10: KG | L10: #REF!
B11: CH-GL0547-2WV | C11: 2127A | D11: CHUN HUA | E11: RFMI | F11: GLAZE BASE CH-10 | G11: I | H11: 1058 | I11: 10.686 | J11: KG | L11: #REF!
B12: CH-GL0570WV | C12: 2127A | D12: CHUN HUA | E12: RFMI | F12: GLAZE BASE CH-13 | G12: I | H12: 1058 | I12: 10.69 | J12: KG | L12: #REF!
B13: CH-GL0901WV | C13: 2127A | D13: CHUN HUA | E13: RFMI | F13: DARK YELLOW TINT FOR GLAZE | G13: I | H13: 1058 | I13: 10.69 | J13: KG | L13: #REF!
B14: CH-GL0902WV | C14: 2127A | D14: CHUN HUA | E14: RFMI | F14: RED OXIDE TINT PASTE CH | G14: I | H14: 1058 | I14: 14.571 | J14: KG | L14: #REF!
B15: CH-GL0905WV | C15: 2127A | D15: CHUN HUA | E15: RFMI | F15: LITE YELLOW TINT PASTE CH | G15: I | H15: 1058 | I15: 22.343 | J15: KG | L15: #REF!
B16: CH-JF0003WV | C16: 2127A | D16: CHUN HUA | E16: RFMI | F16: GOLD | G16: I | H16: 1121 | I16: 29.95 | J16: KG | L16: #REF!
B17: CH-JF0004WV | C17: 2127A | D17: CHUN HUA | E17: RFMI | F17: RED GOLD POWDER | G17: I | H17: 1121 | I17: 29.95 | J17: KG | L17: #REF!
B18: CH-JS0934WV | C18: 2127A | D18: CHUN HUA | E18: RFMI | F18: RED ALCOHOL TINT PASTE CH | G18: I | H18: 1058 | I18: 22.667 | J18: KG | L18: #REF!
B19: CH-JS0935WV | C19: 2127A | D19: CHUN HUA | E19: RFMI | F19: YELLOW ALCOHOL TINT PASTE CH | G19: I | H19: 1058 | I19: 22.667 | J19: KG | L19: #REF!
B20: CH-JS0936WV | C20: 2127A | D20: CHUN HUA | E20: RFMI | F20: BLACK ALCOHOL TINT PASTE CH | G20: I | H20: 1058 | I20: 22.67 | J20: KG | L20: #REF!
B21: CH-NM0225-5WV | C21: 2127A | D21: CHUN HUA | E21: RFMI | F21: TOP COAT-1 | G21: I | L21: #REF!
B22: CH-NS9252WV | C22: 2127A | D22: CHUN HUA | E22: RFMI | F22: RED TINT PASTE CH | G22: I | H22: 1058 | I22: 4.29 | J22: KG | L22: #REF!
B23: CH-YF0706WV | C23: 2127A | D23: CHUN HUA | E23: RFMI | F23: SILVER CH-2 | G23: I | L23: #REF!
B24: CH-YF8196WV | C24: 2127A | D24: CHUN HUA | E24: RFMI | F24: SILVER CH-3 | G24: I | L24: #REF!
B25: CH-YF8801WV | C25: 2127A | D25: CHUN HUA | E25: RFMI | F25: SILVER CH-4 | G25: I | H25: 1058 | I25: 25.1 | J25: KG | L25: #REF!
B26: 100068 | C26: 2057A | D26: D.V.PHU | E26: ELIT | F26: U-ELITE50"X2.OZ BLACK 70G | G26: D | L26: #REF!
B27: 100094 | C27: 2013A | D27: THU HIEN.C | E27: MIS | F27: 3.97MM YELLOW POLYESTER WELT | G27: D | L27: #REF!
B28: 100129 | C28: 2019A | D28: MIREA | E28: UEFB | F28: 0.75 OZ LOWMELT FIBER 48" | G28: D | L28: #REF!
B29: 100131 | C29: 3A | D29: Wanvog | E29: MIS | F29: 8/32" WELT CORD | G29: I | L29: #REF!
B30: 100161 | C30: 2019A | D30: MIREA | E30: UEFB | F30: 0.75 OZ LOWMELT FIBER 34" | G30: D | L30: #REF!
B31: 100308 | C31: 2139A | D31: MINGLU | E31: MISN | F31: U-TYPAR 49 INCH 4.5OZ/SQYD | G31: I | H31: 1010 | I31: 0.6023 | J31: M | L31: #REF!
B32: 100347 | C32: 2139A | D32: MINGLU | E32: MIS | F32: UL 150 PAD 3.5 INCH WIDE | G32: I | L32: #REF!
B33: 100350 | C33: 2060A | D33: DAI NGOC | E33: UECD | F33: RECYCLE CARDBOARD1.6X1000X1100 | G33: D | L33: #REF!
B34: 100421 | C34: 2057A | D34: D.V.PHU | E34: ELIT | F34: U-ELITE36"X2.OZ BLACK 70G | G34: D | L34: #REF!
B35: 100422 | C35: 2058A | D35: VISON | E35: ELIT | F35: U-ELITE38"X2.OZ BLACK 70G | G35: D | L35: #REF!
B36: 100434 | C36: 2019A | D36: MIREA | E36: UEFB | F36: 0.75OZ LOWMELT FIBER 50 INCH | G36: D | L36: #REF!
B37: 100458 | C37: 3A | D37: Wanvog | E37: MIS | F37: 1" WIDTH BLACK VELCRO LOOP | G37: I | H37: 1018 | I37: 0.0433 | J37: M | L37: #REF!
B38: 100459 | C38: 3A | D38: Wanvog | E38: MIS | F38: 1" WIDTH BLACK VELCRO HOOK | G38: I | H38: 1017 | I38: 0.0433 | J38: M | L38: #REF!
B39: 100477 | C39: 2139A | D39: MINGLU | E39: MIS | F39: UL 150 PAD 22 INCH WIDE | G39: I | L39: #REF!
B40: 100499 | C40: 2057A | D40: D.V.PHU | E40: ELIT | F40: ELITE40"X1OZ WHITE 35G | G40: D | L40: #REF!
B41: 100503 | C41: 3A | D41: Wanvog | E41: RFG | F41: FRINGE VICTORIA 89001/59701 | G41: I | L41: #REF!
...

Sheet PO
B1: WANEK FURNITURE CO., LTD
B2: Tan Long Hamlet, Tan Hiep Ward, Tan Uyen District, Binh Duong Province, VN
B3: Tel: +84 650.3655200
B4: Fax: +84 650.3655192
B5: VAT CODE: 3700937241
B7: PURCHASE ORDER ( RAW MATERIAL)
A9: VENDOR: | B9: =+#REF! | C9: PO No: | D9: =+#REF!
A10: ADDRESS: | B10: =+#REF! | C10: DATE: | D10: 41387
C11: BUYER: | D11: JANE VO
A12: CONTACT PERSON : | B12: JACK | C12: TEL: | D12: 0650 3655200 (7036)
A13: TEL | B13: 0571 8298 8710 | C13: FAX: | D13: 0650 3655200 (7036)
A14: FAX | B14: 0571 8217 1016
A15: Ship to: | B15: Wanek Furniture Co., Ltd. | C15: SPECIAL INSTRUCTIONS: Port of loading : SHANGHAI
B16: Tan Long Hamlet, Tan Hiep Ward, Tan Uyen District | C16: Port of destination: Ho Chi Minh Port, Vietnam
B17: Binh Duong Province, Vietnam | C17: Required documents: Invoice, Packing list, B/L, C/O
C18: Origin : CHINA
A19: SHIPPING TERMS | C19: DELIVERY INSTRUCTIONS | E19: PAYMENT TERMS
A20: FOB SHANGHAI | D20: 41416 | E20: B45 T/T 45 days B/L days
A21: INCOTERMS 2000 | C21: To be delivered on (YYY/MM/DD) or as postponed by noticed from purchaser. | E21: STANDARD CHARTERED BANK (VIETNAM) LTD-HCMC BRANCH
E22: ADD: G11-SAIGON TRADE CENTER, DIST 1, HCM, VN
E23: ACC NO: 99102870712
A24: ITEM No. | B24: DESCRIPTION AND INSTRUCTION | C24: UNIT | D24: QUANTITY | E24: UNIT PRICE (USD) | F24: AMOUNT (USD)
A25: =+INVOICE!B25 | B25: =+INVOICE!C25 | C25: LM | D25: =+INVOICE!D25 | E25: =+INVOICE!#REF! | F25: =+D25*E25
B26: 100% Polyester
A27: =+INVOICE!#REF! | B27: =+INVOICE!#REF! | C27: LM | D27: =+INVOICE!#REF! | E27: =+INVOICE!#REF! | F27: =+E27*D27
B28: 100% Polyester
A38: Freight and Insurance charge
A39: TOTAL AMOUNT: | F39: =SUM(F25:G38)
A41: 1.The PO No. must appear on all packing lists, shipping documents, invoices and correspondence.
A42: 2.All goods and services are subject to purchaser's inspection and acceptance.
A43: 3.All goods shall be packed sufficiently to prevent loss, corrosion or damage during loading, transit, off-loading, handling, etc.
A44: 4.All rejected goods will be charged back to seller, including transportation and handling costs.
A45: 5.All over shipments will be accepted as free of charge deliveries. Exception: UOM's SF and M will be given a + 2% tolerance.
A46: 6.Seller must receive written approval from Wanek in advance for all under shipments, shipping with freight charge collect, combining / marking / packing with any other orders or a penalty of 3% of invoice value will be charged.
A47: 7.For each day that the delivery date is later than the due date, seller will be charged 3% of the invoice value.
A48: 8.If goods do not meet agreed standards and specifications,purchaser has the right to return, reject, charge back the seller.
A49: 9.All technical and commercial documentation called for in form attached is an integral part of vendor scope of supply. In the event vendor fail to furnish Wanek the requirements, an amount of up to 3% of invoice value will be withheld until the full and
A50: correct documentation requirements are submitted to Wanek.
A51: 10.Seller agrees to hold harmless the purchaser on any infringement of patent, trademark, copyright on this PO.
A52: 11.Seller agrees to sign, chop and fax this PO back to Wanek within 24 hours of PO receipt.
